<?xml version="1.0" encoding="UTF-8"?>
<testsuite name="FileServerTest" tests="1" skipped="0" failures="1" errors="0" timestamp="2022-04-17T09:45:11" hostname="serj-GF63-Thin-9RCX" time="0.523">
  <properties/>
  <testcase name="start" classname="FileServerTest" time="0.523">
    <failure message="java.lang.AssertionError: Wrong answer in test #1&#10;&#10;Can't find just saved file in the /server/data folder!&#10;&#10;Please find below the output of your program during this failed test.&#10;Note that the '&gt;' character indicates the beginning of the input line.&#10;&#10;---&#10;&#10;stdout:&#10;Server started!&#10;Client started!&#10;client accepted&#10;Enter action (1 - get a file, 2 - create a file, 3 - delete a file): into run&#10;start to wait info from clie&gt; exit&#10;nt&#10;The request was sent.&#10;Received: exit&#10;the response says that the server has been stopped&#10;Server started!&#10;Client started!&#10;client accepted&#10;Enter action (1 - get a file, 2 - create a file, 3 - delete a file): into run&#10;start to wait info from cli&gt; 2&#10;ent&#10;Enter filename: &gt; test_purpose_5L54QQBI.txt&#10;Enter file content: &gt; US9HDV8D&#10;The request was sent.&#10;Received: PUT test_purpose_5L54QQBI.txt US9HDV8D&#10;IOException in PutProcess&#10;Sent: All files were sent!&#10;start to wait info from client&#10;500&#10;The response says that there is an unexpected error!&#10;Enter action (1 - get a file, 2 - create a file, 3 - delete a file):&#10;&#10;stderr:&#10;Exception in thread &quot;Thread-4&quot; org.hyperskill.hstest.dynamic.security.ExitException: Tried to exit with status 0.&#10;&#9;at org.hyperskill.hstest.dynamic.security.TestingSecurityManager.checkExit(TestingSecurityManager.java:50)&#10;&#9;at java.base/java.lang.Runtime.exit(Runtime.java:113)&#10;&#9;at java.base/java.lang.System.exit(System.java:1860)&#10;&#9;at server.Session.run(Session.java:44)&#10;java.net.BindException: Address already in use&#10;&#9;at java.base/sun.nio.ch.Net.bind0(Native Method)&#10;&#9;at java.base/sun.nio.ch.Net.bind(Net.java:555)&#10;&#9;at java.base/sun.nio.ch.Net.bind(Net.java:544)&#10;&#9;at java.base/sun.nio.ch.NioSocketImpl.bind(NioSocketImpl.java:643)&#10;&#9;at java.base/java.net.ServerSocket.bind(ServerSocket.java:388)&#10;&#9;at java.base/java.net.ServerSocket.&lt;init&gt;(ServerSocket.java:274)&#10;&#9;at java.base/java.net.ServerSocket.&lt;init&gt;(ServerSocket.java:167)&#10;&#9;at server.PortListening.run(PortListening.java:15)&#10;java.io.FileNotFoundException: ./File Server/task/src/server/data/test_purpose_5L54QQBI.txt (No such file or directory)&#10;&#9;at java.base/java.io.FileOutputStream.open0(Native Method)&#10;&#9;at java.base/java.io.FileOutputStream.open(FileOutputStream.java:293)&#10;&#9;at java.base/java.io.FileOutputStream.&lt;init&gt;(FileOutputStream.java:235)&#10;&#9;at java.base/java.io.FileOutputStream.&lt;init&gt;(FileOutputStream.java:184)&#10;&#9;at java.base/java.io.FileWriter.&lt;init&gt;(FileWriter.java:96)&#10;&#9;at server.QueryProcessing.PutProcess(QueryProcessing.java:22)&#10;&#9;at server.Session.run(Session.java:30)&#10;java.net.BindException: Address already in use&#10;&#9;at java.base/sun.nio.ch.Net.bind0(Native Method)&#10;&#9;at java.base/sun.nio.ch.Net.bind(Net.java:555)&#10;&#9;at java.base/sun.nio.ch.Net.bind(Net.java:544)&#10;&#9;at java.b" type="java.lang.AssertionError">java.lang.AssertionError: Wrong answer in test #1

Can't find just saved file in the /server/data folder!

Please find below the output of your program during this failed test.
Note that the '&gt;' character indicates the beginning of the input line.

---

stdout:
Server started!
Client started!
client accepted
Enter action (1 - get a file, 2 - create a file, 3 - delete a file): into run
start to wait info from clie&gt; exit
nt
The request was sent.
Received: exit
the response says that the server has been stopped
Server started!
Client started!
client accepted
Enter action (1 - get a file, 2 - create a file, 3 - delete a file): into run
start to wait info from cli&gt; 2
ent
Enter filename: &gt; test_purpose_5L54QQBI.txt
Enter file content: &gt; US9HDV8D
The request was sent.
Received: PUT test_purpose_5L54QQBI.txt US9HDV8D
IOException in PutProcess
Sent: All files were sent!
start to wait info from client
500
The response says that there is an unexpected error!
Enter action (1 - get a file, 2 - create a file, 3 - delete a file):

stderr:
Exception in thread &quot;Thread-4&quot; org.hyperskill.hstest.dynamic.security.ExitException: Tried to exit with status 0.
	at org.hyperskill.hstest.dynamic.security.TestingSecurityManager.checkExit(TestingSecurityManager.java:50)
	at java.base/java.lang.Runtime.exit(Runtime.java:113)
	at java.base/java.lang.System.exit(System.java:1860)
	at server.Session.run(Session.java:44)
java.net.BindException: Address already in use
	at java.base/sun.nio.ch.Net.bind0(Native Method)
	at java.base/sun.nio.ch.Net.bind(Net.java:555)
	at java.base/sun.nio.ch.Net.bind(Net.java:544)
	at java.base/sun.nio.ch.NioSocketImpl.bind(NioSocketImpl.java:643)
	at java.base/java.net.ServerSocket.bind(ServerSocket.java:388)
	at java.base/java.net.ServerSocket.&lt;init&gt;(ServerSocket.java:274)
	at java.base/java.net.ServerSocket.&lt;init&gt;(ServerSocket.java:167)
	at server.PortListening.run(PortListening.java:15)
java.io.FileNotFoundException: ./File Server/task/src/server/data/test_purpose_5L54QQBI.txt (No such file or directory)
	at java.base/java.io.FileOutputStream.open0(Native Method)
	at java.base/java.io.FileOutputStream.open(FileOutputStream.java:293)
	at java.base/java.io.FileOutputStream.&lt;init&gt;(FileOutputStream.java:235)
	at java.base/java.io.FileOutputStream.&lt;init&gt;(FileOutputStream.java:184)
	at java.base/java.io.FileWriter.&lt;init&gt;(FileWriter.java:96)
	at server.QueryProcessing.PutProcess(QueryProcessing.java:22)
	at server.Session.run(Session.java:30)
java.net.BindException: Address already in use
	at java.base/sun.nio.ch.Net.bind0(Native Method)
	at java.base/sun.nio.ch.Net.bind(Net.java:555)
	at java.base/sun.nio.ch.Net.bind(Net.java:544)
	at java.b
	at org.junit.Assert.fail(Assert.java:88)
	at org.hyperskill.hstest.stage.StageTest.start(StageTest.java:155)
	at java.base/jdk.internal.reflect.NativeMethodAccessorImpl.invoke0(Native Method)
	at java.base/jdk.internal.reflect.NativeMethodAccessorImpl.invoke(NativeMethodAccessorImpl.java:77)
	at java.base/jdk.internal.reflect.DelegatingMethodAccessorImpl.invoke(DelegatingMethodAccessorImpl.java:43)
	at java.base/java.lang.reflect.Method.invoke(Method.java:568)
	at org.junit.runners.model.FrameworkMethod$1.runReflectiveCall(FrameworkMethod.java:50)
	at org.junit.internal.runners.model.ReflectiveCallable.run(ReflectiveCallable.java:12)
	at org.junit.runners.model.FrameworkMethod.invokeExplosively(FrameworkMethod.java:47)
	at org.junit.internal.runners.statements.InvokeMethod.evaluate(InvokeMethod.java:17)
	at org.junit.runners.ParentRunner.runLeaf(ParentRunner.java:325)
	at org.junit.runners.BlockJUnit4ClassRunner.runChild(BlockJUnit4ClassRunner.java:78)
	at org.junit.runners.BlockJUnit4ClassRunner.runChild(BlockJUnit4ClassRunner.java:57)
	at org.junit.runners.ParentRunner$3.run(ParentRunner.java:290)
	at org.junit.runners.ParentRunner$1.schedule(ParentRunner.java:71)
	at org.junit.runners.ParentRunner.runChildren(ParentRunner.java:288)
	at org.junit.runners.ParentRunner.access$000(ParentRunner.java:58)
	at org.junit.runners.ParentRunner$2.evaluate(ParentRunner.java:268)
	at org.junit.internal.runners.statements.RunAfters.evaluate(RunAfters.java:27)
	at org.junit.runners.ParentRunner.run(ParentRunner.java:363)
	at org.gradle.api.internal.tasks.testing.junit.JUnitTestClassExecutor.runTestClass(JUnitTestClassExecutor.java:110)
	at org.gradle.api.internal.tasks.testing.junit.JUnitTestClassExecutor.execute(JUnitTestClassExecutor.java:58)
	at org.gradle.api.internal.tasks.testing.junit.JUnitTestClassExecutor.execute(JUnitTestClassExecutor.java:38)
	at org.gradle.api.internal.tasks.testing.junit.AbstractJUnitTestClassProcessor.processTestClass(AbstractJUnitTestClassProcessor.java:62)
	at org.gradle.api.internal.tasks.testing.SuiteTestClassProcessor.processTestClass(SuiteTestClassProcessor.java:51)
	at java.base/jdk.internal.reflect.NativeMethodAccessorImpl.invoke0(Native Method)
	at java.base/jdk.internal.reflect.NativeMethodAccessorImpl.invoke(NativeMethodAccessorImpl.java:77)
	at java.base/jdk.internal.reflect.DelegatingMethodAccessorImpl.invoke(DelegatingMethodAccessorImpl.java:43)
	at java.base/java.lang.reflect.Method.invoke(Method.java:568)
	at org.gradle.internal.dispatch.ReflectionDispatch.dispatch(ReflectionDispatch.java:36)
	at org.gradle.internal.dispatch.ReflectionDispatch.dispatch(ReflectionDispatch.java:24)
	at org.gradle.internal.dispatch.ContextClassLoaderDispatch.dispatch(ContextClassLoaderDispatch.java:33)
	at org.gradle.internal.dispatch.ProxyDispatchAdapter$DispatchingInvocationHandler.invoke(ProxyDispatchAdapter.java:94)
	at jdk.proxy1/jdk.proxy1.$Proxy2.processTestClass(Unknown Source)
	at org.gradle.api.internal.tasks.testing.worker.TestWorker$2.run(TestWorker.java:176)
	at org.gradle.api.internal.tasks.testing.worker.TestWorker.executeAndMaintainThreadName(TestWorker.java:129)
	at org.gradle.api.internal.tasks.testing.worker.TestWorker.execute(TestWorker.java:100)
	at org.gradle.api.internal.tasks.testing.worker.TestWorker.execute(TestWorker.java:60)
	at org.gradle.process.internal.worker.child.ActionExecutionWorker.execute(ActionExecutionWorker.java:56)
	at org.gradle.process.internal.worker.child.SystemApplicationClassLoaderWorker.call(SystemApplicationClassLoaderWorker.java:133)
	at org.gradle.process.internal.worker.child.SystemApplicationClassLoaderWorker.call(SystemApplicationClassLoaderWorker.java:71)
	at worker.org.gradle.process.internal.worker.GradleWorkerMain.run(GradleWorkerMain.java:69)
	at worker.org.gradle.process.internal.worker.GradleWorkerMain.main(GradleWorkerMain.java:74)
</failure>
  </testcase>
  <system-out><![CDATA[?[1;31m
Start test 1?[0m
Server started!
Client started!
client accepted
into run
Enter action (1 - get a file, 2 - create a file, 3 - delete a file): > exit
start to wait info from client
The request was sent.
Received: exit
the response says that the server has been stopped
Server started!
Client started!
client accepted
into run
Enter action (1 - get a file, 2 - create a file, 3 - delete a file): > 2
start to wait info from client
Enter filename: > test_purpose_5L54QQBI.txt
Enter file content: > US9HDV8D
The request was sent.
Received: PUT test_purpose_5L54QQBI.txt US9HDV8D
IOException in PutProcess
Sent: All files were sent!
start to wait info from client
500
The response says that there is an unexpected error!
]]></system-out>
  <system-err><![CDATA[Exception in thread "Thread-4" org.hyperskill.hstest.dynamic.security.ExitException: Tried to exit with status 0.
	at org.hyperskill.hstest.dynamic.security.TestingSecurityManager.checkExit(TestingSecurityManager.java:50)
	at java.base/java.lang.Runtime.exit(Runtime.java:113)
	at java.base/java.lang.System.exit(System.java:1860)
	at server.Session.run(Session.java:44)
java.net.BindException: Address already in use
	at java.base/sun.nio.ch.Net.bind0(Native Method)
	at java.base/sun.nio.ch.Net.bind(Net.java:555)
	at java.base/sun.nio.ch.Net.bind(Net.java:544)
	at java.base/sun.nio.ch.NioSocketImpl.bind(NioSocketImpl.java:643)
	at java.base/java.net.ServerSocket.bind(ServerSocket.java:388)
	at java.base/java.net.ServerSocket.<init>(ServerSocket.java:274)
	at java.base/java.net.ServerSocket.<init>(ServerSocket.java:167)
	at server.PortListening.run(PortListening.java:15)
java.io.FileNotFoundException: ./File Server/task/src/server/data/test_purpose_5L54QQBI.txt (No such file or directory)
	at java.base/java.io.FileOutputStream.open0(Native Method)
	at java.base/java.io.FileOutputStream.open(FileOutputStream.java:293)
	at java.base/java.io.FileOutputStream.<init>(FileOutputStream.java:235)
	at java.base/java.io.FileOutputStream.<init>(FileOutputStream.java:184)
	at java.base/java.io.FileWriter.<init>(FileWriter.java:96)
	at server.QueryProcessing.PutProcess(QueryProcessing.java:22)
	at server.Session.run(Session.java:30)
java.net.BindException: Address already in use
	at java.base/sun.nio.ch.Net.bind0(Native Method)
	at java.base/sun.nio.ch.Net.bind(Net.java:555)
	at java.base/sun.nio.ch.Net.bind(Net.java:544)
	at java.base/sun.nio.ch.NioSocketImpl.bind(NioSocketImpl.java:643)
	at java.base/java.net.ServerSocket.bind(ServerSocket.java:388)
	at java.base/java.net.ServerSocket.<init>(ServerSocket.java:274)
	at java.base/java.net.ServerSocket.<init>(ServerSocket.java:167)
	at server.PortListening.run(PortListening.java:15)
java.net.BindException: Address already in use
	at java.base/sun.nio.ch.Net.bind0(Native Method)
	at java.base/sun.nio.ch.Net.bind(Net.java:555)
	at java.base/sun.nio.ch.Net.bind(Net.java:544)
	at java.base/sun.nio.ch.NioSocketImpl.bind(NioSocketImpl.java:643)
	at java.base/java.net.ServerSocket.bind(ServerSocket.java:388)
	at java.base/java.net.ServerSocket.<init>(ServerSocket.java:274)
	at java.base/java.net.ServerSocket.<init>(ServerSocket.java:167)
	at server.PortListening.run(PortListening.java:15)
java.net.BindException: Address already in use
	at java.base/sun.nio.ch.Net.bind0(Native Method)
	at java.base/sun.nio.ch.Net.bind(Net.java:555)
	at java.base/sun.nio.ch.Net.bind(Net.java:544)
	at java.base/sun.nio.ch.NioSocketImpl.bind(NioSocketImpl.java:643)
]]></system-err>
</testsuite>
